Workbook

Sheet Master
A1: Date | B1: Gold Price | C1: USD | D1: Brent | E1: Repo | F1: CPI | G1: Lag 1
A2: 42370 | B2: 24943 | C2: 66.3 | D2: 36 | E2: 6.75 | F2: =_xlfn.XLOOKUP(A2, CPI!D:D, CPI!C:C, "", -1) -> 5.69 | G2: 0
A3: 42373 | B3: 25423 | C3: 66.43 | D3: =_xlfn.XLOOKUP(A3, Brent!A:A, Brent!B:B, "") -> 36.28 | E3: 6.75 | F3: =_xlfn.XLOOKUP( A3, CPI!D:D, CPI!C:C, "", -1 ) -> 5.69 | G3: 24943
A4: 42374 | B4: 25430 | C4: 66.59 | D4: =_xlfn.XLOOKUP(A4, Brent!A:A, Brent!B:B, "") -> 35.56 | E4: 6.75 | F4: =_xlfn.XLOOKUP( A4, CPI!D:D, CPI!C:C, "", -1 ) -> 5.69 | G4: 25423
A5: 42375 | B5: 25756 | C5: 66.7 | D5: =_xlfn.XLOOKUP(A5, Brent!A:A, Brent!B:B, "") -> 33.89 | E5: 6.75 | F5: =_xlfn.XLOOKUP( A5, CPI!D:D, CPI!C:C, "", -1 ) -> 5.69 | G5: 25430
A6: 42376 | B6: 26106 | C6: 66.85 | D6: =_xlfn.XLOOKUP(A6, Brent!A:A, Brent!B:B, "") -> 33.57 | E6: 6.75 | F6: =_xlfn.XLOOKUP( A6, CPI!D:D, CPI!C:C, "", -1 ) -> 5.69 | G6: 25756
A7: 42377 | B7: 25989 | C7: 66.79 | D7: =_xlfn.XLOOKUP(A7, Brent!A:A, Brent!B:B, "") -> 31.67 | E7: 6.75 | F7: =_xlfn.XLOOKUP( A7, CPI!D:D, CPI!C:C, "", -1 ) -> 5.69 | G7: 26106
A8: 42380 | B8: 25877 | C8: 66.78 | D8: =_xlfn.XLOOKUP(A8, Brent!A:A, Brent!B:B, "") -> 30.14 | E8: 6.75 | F8: =_xlfn.XLOOKUP( A8, CPI!D:D, CPI!C:C, "", -1 ) -> 5.69 | G8: 25989
A9: 42381 | B9: 25689 | C9: 66.9 | D9: =_xlfn.XLOOKUP(A9, Brent!A:A, Brent!B:B, "") -> 29.14 | E9: 6.75 | F9: =_xlfn.XLOOKUP( A9, CPI!D:D, CPI!C:C, "", -1 ) -> 5.69 | G9: 25877
A10: 42382 | B10: 25750 | C10: 66.91 | D10: =_xlfn.XLOOKUP(A10, Brent!A:A, Brent!B:B, "") -> 28.58 | E10: 6.75 | F10: =_xlfn.XLOOKUP( A10, CPI!D:D, CPI!C:C, "", -1 ) -> 5.69 | G10: 25689
A11: 42383 | B11: 25652 | C11: 66.17 | D11: =_xlfn.XLOOKUP(A11, Brent!A:A, Brent!B:B, "") -> 28.84 | E11: 6.75 | F11: =_xlfn.XLOOKUP( A11, CPI!D:D, CPI!C:C, "", -1 ) -> 5.69 | G11: 25750
A12: 42384 | B12: 26126 | C12: 66.61 | D12: =_xlfn.XLOOKUP(A12, Brent!A:A, Brent!B:B, "") -> 28.8 | E12: 6.75 | F12: =_xlfn.XLOOKUP( A12, CPI!D:D, CPI!C:C, "", -1 ) -> 5.69 | G12: 25652
A13: 42387 | B13: 26070 | C13: 66.73 | D13: =_xlfn.XLOOKUP(A13, Brent!A:A, Brent!B:B, "") -> 27.36 | E13: 6.75 | F13: =_xlfn.XLOOKUP( A13, CPI!D:D, CPI!C:C, "", -1 ) -> 5.69 | G13: 26126
A14: 42388 | B14: 26064 | C14: 66.71 | D14: =_xlfn.XLOOKUP(A14, Brent!A:A, Brent!B:B, "") -> 27.36 | E14: 6.75 | F14: =_xlfn.XLOOKUP( A14, CPI!D:D, CPI!C:C, "", -1 ) -> 5.69 | G14: 26070
... A16: 42390 | B16: 26190 | C16: 66.84 | D16: =_xlfn.XLOOKUP(A16, Brent!A:A, Brent!B:B, "") -> 27.59 | E16: 6.75 | F16: =_xlfn.XLOOKUP( A16, CPI!D:D, CPI!C:C, "", -1 ) -> 5.69 | G16: 26563
A17: 42391 | B17: 26168 | C17: =_xlfn.XLOOKUP(A17, USD!A:A, USD!B:B, "") -> 67.549 | D17: =_xlfn.XLOOKUP(A17, Brent!A:A, Brent!B:B, "") -> 30.46 | E17: 6.75 | F17: =_xlfn.XLOOKUP( A17, CPI!D:D, CPI!C:C, "", -1 ) -> 5.69 | G17: 26190
A18: 42394 | B18: 26391 | C18: =_xlfn.XLOOKUP(A18, USD!A:A, USD!B:B, "") -> 67.755 | D18: =_xlfn.XLOOKUP(A18, Brent!A:A, Brent!B:B, "") -> 29.82 | E18: 6.75 | F18: =_xlfn.XLOOKUP( A18, CPI!D:D, CPI!C:C, "", -1 ) -> 5.69 | G18: 26168
A19: 42396 | B19: 26736 | C19: =_xlfn.XLOOKUP(A19, USD!A:A, USD!B:B, "") -> 68.144 | D19: =_xlfn.XLOOKUP(A19, Brent!A:A, Brent!B:B, "") -> 31.83 | E19: 6.75 | F19: =_xlfn.XLOOKUP( A19, CPI!D:D, CPI!C:C, "", -1 ) -> 5.69 | G19: 26391
A20: 42397 | B20: 26701 | C20: =_xlfn.XLOOKUP(A20, USD!A:A, USD!B:B, "") -> 68.053 | D20: =_xlfn.XLOOKUP(A20, Brent!A:A, Brent!B:B, "") -> 33.01 | E20: 6.75 | F20: =_xlfn.XLOOKUP( A20, CPI!D:D, CPI!C:C, "", -1 ) -> 5.69 | G20: 26736
A21: 42398 | B21: 26709 | C21: =_xlfn.XLOOKUP(A21, USD!A:A, USD!B:B, "") -> 67.878 | D21: =_xlfn.XLOOKUP(A21, Brent!A:A, Brent!B:B, "") -> 33.14 | E21: 6.75 | F21: =_xlfn.XLOOKUP( A21, CPI!D:D, CPI!C:C, "", -1 ) -> 5.69 | G21: 26701
A22: 42401 | B22: 26973 | C22: =_xlfn.XLOOKUP(A22, USD!A:A, USD!B:B, "") -> 67.835 | D22: =_xlfn.XLOOKUP(A22, Brent!A:A, Brent!B:B, "") -> 32.45 | E22: 6.75 | F22: =_xlfn.XLOOKUP( A22, CPI!D:D, CPI!C:C, "", -1 ) -> 5.26 | G22: 26709
A23: 42402 | B23: 27008 | C23: =_xlfn.XLOOKUP(A23, USD!A:A, USD!B:B, "") -> 67.975 | D23: =_xlfn.XLOOKUP(A23, Brent!A:A, Brent!B:B, "") -> 30.98 | E23: 6.75 | F23: =_xlfn.XLOOKUP( A23, CPI!D:D, CPI!C:C, "", -1 ) -> 5.26 | G23: 26973
A24: 42403 | B24: 27285 | C24: =_xlfn.XLOOKUP(A24, USD!A:A, USD!B:B, "") -> 67.934 | D24: =_xlfn.XLOOKUP(A24, Brent!A:A, Brent!B:B, "") -> 32.38 | E24: 6.75 | F24: =_xlfn.XLOOKUP( A24, CPI!D:D, CPI!C:C, "", -1 ) -> 5.26 | G24: 27008
A25: 42404 | B25: 27656 | C25: =_xlfn.XLOOKUP(A25, USD!A:A, USD!B:B, "") -> 67.544 | D25: =_xlfn.XLOOKUP(A25, Brent!A:A, Brent!B:B, "") -> 32.76 | E25: 6.75 | F25: =_xlfn.XLOOKUP( A25, CPI!D:D, CPI!C:C, "", -1 ) -> 5.26 | G25: 27285
A26: 42405 | B26: 27568 | C26: =_xlfn.XLOOKUP(A26, USD!A:A, USD!B:B, "") -> 67.81 | D26: =_xlfn.XLOOKUP(A26, Brent!A:A, Brent!B:B, "") -> 32.35 | E26: 6.75 | F26: =_xlfn.XLOOKUP( A26, CPI!D:D, CPI!C:C, "", -1 ) -> 5.26 | G26: 27656
A27: 42408 | B27: 28367 | C27: =_xlfn.XLOOKUP(A27, USD!A:A, USD!B:B, "") -> 68.034 | D27: =_xlfn.XLOOKUP(A27, Brent!A:A, Brent!B:B, "") -> 31.64 | E27: 6.75 | F27: =_xlfn.XLOOKUP( A27, CPI!D:D, CPI!C:C, "", -1 ) -> 5.26 | G27: 27568
A28: 42409 | B28: 28325 | C28: =_xlfn.XLOOKUP(A28, USD!A:A, USD!B:B, "") -> 67.901 | D28: =_xlfn.XLOOKUP(A28, Brent!A:A, Brent!B:B, "") -> 30.15 | E28: 6.75 | F28: =_xlfn.XLOOKUP( A28, CPI!D:D, CPI!C:C, "", -1 ) -> 5.26 | G28: 28367
... A40: 42426 | B40: 29290 | C40: =_xlfn.XLOOKUP(A40, USD!A:A, USD!B:B, "") -> 68.737 | D40: =_xlfn.XLOOKUP(A40, Brent!A:A, Brent!B:B, "") -> 35.76 | E40: 6.75 | F40: =_xlfn.XLOOKUP( A40, CPI!D:D, CPI!C:C, "", -1 ) -> 5.26 | G40: 29735
A41: 42429 | B41: 29437 | C41: =_xlfn.XLOOKUP(A41, USD!A:A, USD!B:B, "") -> 68.208 | D41: =_xlfn.XLOOKUP(A41, Brent!A:A, Brent!B:B, "") -> 35.92 | E41: =_xlfn.XLOOKUP(A41, Repo!A:A, Repo!B:B, "") -> 6.75 | F41: =_xlfn.XLOOKUP( A41, CPI!D:D, CPI!C:C, "", -1 ) -> 5.26 | G41: 29290
A42: 42430 | B42: 29097 | C42: =_xlfn.XLOOKUP(A42, USD!A:A, USD!B:B, "") -> 67.753 | D42: =_xlfn.XLOOKUP(A42, Brent!A:A, Brent!B:B, "") -> 35.73 | E42: 6.75 | F42: =_xlfn.XLOOKUP( A42, CPI!D:D, CPI!C:C, "", -1 ) -> 4.83 | G42: 29437
A43: 42431 | B43: 29219 | C43: =_xlfn.XLOOKUP(A43, USD!A:A, USD!B:B, "") -> 67.395 | D43: =_xlfn.XLOOKUP(A43, Brent!A:A, Brent!B:B, "") -> 36.38 | E43: 6.75 | F43: =_xlfn.XLOOKUP( A43, CPI!D:D, CPI!C:C, "", -1 ) -> 4.83 | G43: 29097
A44: 42432 | B44: 29381 | C44: =_xlfn.XLOOKUP(A44, USD!A:A, USD!B:B, "") -> 67.122 | D44: =_xlfn.XLOOKUP(A44, Brent!A:A, Brent!B:B, "") -> 35.75 | E44: 6.75 | F44: =_xlfn.XLOOKUP( A44, CPI!D:D, CPI!C:C, "", -1 ) -> 4.83 | G44: 29219
A45: 42433 | B45: 29519 | C45: =_xlfn.XLOOKUP(A45, USD!A:A, USD!B:B, "") -> 66.938 | D45: =_xlfn.XLOOKUP(A45, Brent!A:A, Brent!B:B, "") -> 37.61 | E45: 6.75 | F45: =_xlfn.XLOOKUP( A45, CPI!D:D, CPI!C:C, "", -1 ) -> 4.83 | G45: 29381
A46: 42436 | B46: 29597 | C46: =_xlfn.XLOOKUP(A46, USD!A:A, USD!B:B, "") -> 66.989 | D46: =_xlfn.XLOOKUP(A46, Brent!A:A, Brent!B:B, "") -> 39.02 | E46: 6.75 | F46: =_xlfn.XLOOKUP( A46, CPI!D:D, CPI!C:C, "", -1 ) -> 4.83 | G46: 29519
A47: 42437 | B47: 29819 | C47: =_xlfn.XLOOKUP(A47, USD!A:A, USD!B:B, "") -> 67.313 | D47: =_xlfn.XLOOKUP(A47, Brent!A:A, Brent!B:B, "") -> 39.16 | E47: 6.75 | F47: =_xlfn.XLOOKUP( A47, CPI!D:D, CPI!C:C, "", -1 ) -> 4.83 | G47: 29597
A48: 42438 | B48: 29597 | C48: =_xlfn.XLOOKUP(A48, USD!A:A, USD!B:B, "") -> 67.128 | D48: =_xlfn.XLOOKUP(A48, Brent!A:A, Brent!B:B, "") -> 40.26 | E48: 6.75 | F48: =_xlfn.XLOOKUP( A48, CPI!D:D, CPI!C:C, "", -1 ) -> 4.83 | G48: 29819
A49: 42439 | B49: 29928 | C49: =_xlfn.XLOOKUP(A49, USD!A:A, USD!B:B, "") -> 67.302 | D49: =_xlfn.XLOOKUP(A49, Brent!A:A, Brent!B:B, "") -> 38.63 | E49: 6.75 | F49: =_xlfn.XLOOKUP( A49, CPI!D:D, CPI!C:C, "", -1 ) -> 4.83 | G49: 29597
A50: 42440 | B50: 29504 | C50: =_xlfn.XLOOKUP(A50, USD!A:A, USD!B:B, "") -> 66.921 | D50: =_xlfn.XLOOKUP(A50, Brent!A:A, Brent!B:B, "") -> 39.41 | E50: 6.75 | F50: =_xlfn.XLOOKUP( A50, CPI!D:D, CPI!C:C, "", -1 ) -> 4.83 | G50: 29928
A51: 42443 | B51: 29204 | C51: =_xlfn.XLOOKUP(A51, USD!A:A, USD!B:B, "") -> 67.138 | D51: =_xlfn.XLOOKUP(A51, Brent!A:A, Brent!B:B, "") -> 38.06 | E51: 6.75 | F51: =_xlfn.XLOOKUP( A51, CPI!D:D, CPI!C:C, "", -1 ) -> 4.83 | G51: 29504
A52: 42444 | B52: 29050 | C52: =_xlfn.XLOOKUP(A52, USD!A:A, USD!B:B, "") -> 67.372 | D52: =_xlfn.XLOOKUP(A52, Brent!A:A, Brent!B:B, "") -> 37.49 | E52: 6.75 | F52: =_xlfn.XLOOKUP( A52, CPI!D:D, CPI!C:C, "", -1 ) -> 4.83 | G52: 29204
...

Sheet USD
A1: Date | B1: Price
A2: 42391 | B2: 67.549
A3: 42394 | B3: 67.755
A4: 42395 | B4: 67.739
A5: 42396 | B5: 68.144
A6: 42397 | B6: 68.053
A7: 42398 | B7: 67.878
A8: 42401 | B8: 67.835
A9: 42402 | B9: 67.975
A10: 42403 | B10: 67.934
A11: 42404 | B11: 67.544
A12: 42405 | B12: 67.81
A13: 42408 | B13: 68.034
... A2611: 46044 | B2611: 91.52

Sheet Brent
A1: observation_date | B1: DCOILBRENTEU
A2: 42373 | B2: 36.28
A3: 42374 | B3: 35.56
A4: 42375 | B4: 33.89
A5: 42376 | B5: 33.57
A6: 42377 | B6: 31.67
A7: 42380 | B7: 30.14
A8: 42381 | B8: 29.14
A9: 42382 | B9: 28.58
A10: 42383 | B10: 28.84
A11: 42384 | B11: 28.8
A12: 42387 | B12: 27.36
A13: 42388 | B13: 27.36
... A31: 42412 | B31: 31.8
A32: 42415
A33: 42416 | B33: 31.09
A34: 42417 | B34: 33.21
A35: 42418 | B35: 33.2
A36: 42419 | B36: 31.66
A37: 42422 | B37: 33.59
A38: 42423 | B38: 31.9
A39: 42424 | B39: 31.5
A40: 42425 | B40: 32.83
A41: 42426 | B41: 35.76
A42: 42429 | B42: 35.92
A43: 42430 | B43: 35.73
A44: 42431 | B44: 36.38
... A60: 42453 | B60: 38.33
A61: 42454
A62: 42457 | B62: 38.33
A63: 42458 | B63: 36.75
A64: 42459 | B64: 36.75
A65: 42460 | B65: 36.75
A66: 42461 | B66: 36.42
A67: 42464 | B67: 36.05
A68: 42465 | B68: 35.88
A69: 42466 | B69: 37.77
A70: 42467 | B70: 37.15
A71: 42468 | B71: 40.71
A72: 42471 | B72: 41.58
...

Sheet CPI
A1: Year | B1: Month | C1: Combined | D1: Date
A2: 2016 | B2: January | C2: 5.69 | D2: =DATE(A2, MONTH("1-"&B2&"-"&A2), 1) -> 42370
A3: 2016 | B3: February | C3: 5.26 | D3: =DATE(A3, MONTH("1-"&B3&"-"&A3), 1) -> 42401
A4: 2016 | B4: March | C4: 4.83 | D4: =DATE(A4, MONTH("1-"&B4&"-"&A4), 1) -> 42430
A5: 2016 | B5: April | C5: 5.47 | D5: =DATE(A5, MONTH("1-"&B5&"-"&A5), 1) -> 42461
A6: 2016 | B6: May | C6: 5.76 | D6: =DATE(A6, MONTH("1-"&B6&"-"&A6), 1) -> 42491
A7: 2016 | B7: June | C7: 5.77 | D7: =DATE(A7, MONTH("1-"&B7&"-"&A7), 1) -> 42522
A8: 2016 | B8: July | C8: 6.07 | D8: =DATE(A8, MONTH("1-"&B8&"-"&A8), 1) -> 42552
A9: 2016 | B9: August | C9: 5.05 | D9: =DATE(A9, MONTH("1-"&B9&"-"&A9), 1) -> 42583
A10: 2016 | B10: September | C10: 4.39 | D10: =DATE(A10, MONTH("1-"&B10&"-"&A10), 1) -> 42614
A11: 2016 | B11: October | C11: 4.2 | D11: =DATE(A11, MONTH("1-"&B11&"-"&A11), 1) -> 42644
A12: 2016 | B12: November | C12: 3.63 | D12: =DATE(A12, MONTH("1-"&B12&"-"&A12), 1) -> 42675
A13: 2016 | B13: December | C13: 3.41 | D13: =DATE(A13, MONTH("1-"&B13&"-"&A13), 1) -> 42705
... A119: 2025 | B119: December | C119: 1.33 | D119: =DATE(A119, MONTH("1-"&B119&"-"&A119), 1) -> 45992

Sheet Repo
A1: Date | B1: 4.1 Policy Repo Rate
A2: 42400 | B2: 6.75
A3: 42429 | B3: 6.75
A4: 42460 | B4: 6.75
A5: 42490 | B5: 6.5
A6: 42521 | B6: 6.5
A7: 42551 | B7: 6.5
A8: 42582 | B8: 6.5
A9: 42613 | B9: 6.5
A10: 42643 | B10: 6.5
A11: 42674 | B11: 6.25
A12: 42704 | B12: 6.25
A13: 42735 | B13: 6.25
... A120: 45991 | B120: 5.5
